<?xml version="1.0" ?>
<!-- =================================================================================== -->
<!-- |    This document was autogenerated by xacro from /home/brayan/catkin_ws/src/rockbreaker_arm_simulator/rockbreaker_description/urdf/rockbreaker_arm.urdf.xacro | -->
<!-- |    EDITING THIS FILE BY HAND IS NOT RECOMMENDED                                 | -->
<!-- =================================================================================== -->
<robot name="rockbreaker_arm">
    <!-- Ros_control plugin -->
    <gazebo>
        <plugin filename="libgazebo_ros_control.so" name="gazebo_ros_control">
            <robotNamespace>/</robotNamespace>
            <robotSimType>gazebo_ros_control/DefaultRobotHWSim</robotSimType>
        </plugin>
    </gazebo>
    <!-- Link Base Rotatoria -->
    <gazebo reference="rockbreaker_base">
        <material>Gazebo/Grey</material>
    </gazebo>
    <!-- Link Base Rotatoria -->
    <gazebo reference="rockbreaker_baserotatoria">
        <material>Gazebo/Yellow</material>
    </gazebo>
    <!-- Link Brazo a -->
    <gazebo reference="brazo_a">
        <material>Gazebo/Yellow</material>
    </gazebo>
    <!-- Link Brazo b -->
    <gazebo reference="brazo_b">
        <material>Gazebo/Yellow</material>
    </gazebo>
    <!-- Link Hammer-->
    <gazebo reference="h_hammer">
        <material>Gazebo/Yellow</material>
    </gazebo>
    <model name="kinect">
        <static>true</static>
        <pose>0 0 0.036 0 0 0</pose>
        <link name="link_camera">
            <inertial>
                <mass>0.1</mass>
            </inertial>
            <collision name="collision">
                <geometry>
                    <box>
                        <size>0.073000 0.276000 0.072000</size>
                    </box>
                </geometry>
            </collision>
            <visual name="visual">
                <geometry>
                    <mesh>
                        <uri>model://kinect/meshes/kinect.dae</uri>
                    </mesh>
                </geometry>
            </visual>
            <sensor name="camera" type="depth">
                <plugin filename="libgazebo_ros_openni_kinect.so" name="camera_plugin">
                    <baseline>0.2</baseline>
                    <alwaysOn>true</alwaysOn>
                    <!-- Keep this zero, update_rate in the parent <sensor> tag
            will control the frame rate. -->
                    <updateRate>0.0</updateRate>
                    <cameraName>camera_ir</cameraName>
                    <imageTopicName>/camera/color/image_raw</imageTopicName>
                    <cameraInfoTopicName>/camera/color/camera_info</cameraInfoTopicName>
                    <depthImageTopicName>/camera/depth/image_raw</depthImageTopicName>
                    <depthImageCameraInfoTopicName>/camera/depth/camera_info</depthImageCameraInfoTopicName>
                    <pointCloudTopicName>/camera/depth/points</pointCloudTopicName>
                    <frameName>camera_link</frameName>
                    <pointCloudCutoff>0.5</pointCloudCutoff>
                    <pointCloudCutoffMax>3000.0</pointCloudCutoffMax>
                    <distortionK1>0</distortionK1>
                    <distortionK2>0</distortionK2>
                    <distortionK3>0</distortionK3>
                    <distortionT1>0</distortionT1>
                    <distortionT2>0</distortionT2>
                    <CxPrime>0</CxPrime>
                    <Cx>0</Cx>
                    <Cy>0</Cy>
                    <focalLength>0</focalLength>
                    <hackBaseline>0</hackBaseline>
                </plugin>
                <update_rate>20</update_rate>
                <camera>
                    <horizontal_fov>1.047198</horizontal_fov>
                    <image>
                        <width>640</width>
                        <height>480</height>
                        <format>R8G8B8</format>
                    </image>
                    <clip>
                        <near>0.05</near>
                        <far>3000</far>
                    </clip>
                </camera>
            </sensor>
        </link>
    </model>
    <!-- Base Fija -->
    <link name="world" />
    <!-- Base Link -->
    <joint name="fixed" type="fixed">
        <parent link="world" />
        <child link="rockbreaker_base" />
        <origin rpy="0 0 1.571" xyz="-3 -3 15.756649" />
    </joint>
    <!-- Base Fija -->
    <link name="rockbreaker_base">
        <visual>
            <origin rpy="0 0 0" xyz="0 0 0" />
            <geometry>
                <mesh filename="package://rockbreaker_arm_simulator/rockbreaker_description/meshes/basefija.dae" scale="1 1 1" />
            </geometry>
        </visual>
        <collision>
            <origin rpy="0 0 0" xyz="0 0 0" />
            <geometry>
                <mesh filename="package://rockbreaker_arm_simulator/rockbreaker_description/meshes/basefija.dae" scale="1 1 1" />
            </geometry>
        </collision>
        <inertial>
            <origin xyz="0 0 0.3" rpy="0 0 0" />
            <mass value="1000" />
            <!-- <inertial>
      <mass value="${mass}" /> -->
            <inertia ixx="541.6664499999999" ixy="0.0" ixz="0.0" iyy="541.6664499999999" iyz="0.0" izz="1041.66625" />
            <!-- </inertial> -->
        </inertial>
    </link>
    <!-- Base Rotatoria -->
    <link name="rockbreaker_baserotatoria">
        <visual>
            <origin rpy="0 0 3.14" xyz="0 0 -0.2" />
            <geometry>
                <mesh filename="package://rockbreaker_arm_simulator/rockbreaker_description/meshes/base_rotatoria.dae" scale="0.1 0.1 0.1" />
            </geometry>
        </visual>
        <collision>
            <origin rpy="0 0 3.14" xyz="0 0 -0.2" />
            <geometry>
                <mesh filename="package://rockbreaker_arm_simulator/rockbreaker_description/meshes/base_rotatoria.dae" scale="0.1 0.1 0.1" />
            </geometry>
        </collision>
        <inertial>
            <origin rpy="0 0 1.57" xyz="0 0 0.2" />
            <mass value="400" />
            <!-- <inertial>
      <mass value="${mass}" /> -->
            <inertia ixx="105.6666244" ixy="0.0" ixz="0.0" iyy="105.6666244" iyz="0.0" izz="130.6666144" />
            <!-- </inertial> -->
        </inertial>
    </link>
    <!-- Brazo A -->
    <link name="brazo_a">
        <visual>
            <origin rpy="0 0.6 1.57" xyz="0 0 -0.2" />
            <geometry>
                <mesh filename="package://rockbreaker_arm_simulator/rockbreaker_description/meshes/BrazoA_rockbreaker.dae" scale="1 1 1" />
            </geometry>
        </visual>
        <collision>
            <origin rpy="0 0.6 1.57" xyz="0 0 -0.2" />
            <geometry>
                <mesh filename="package://rockbreaker_arm_simulator/rockbreaker_description/meshes/BrazoA_rockbreaker.dae" scale="1 1 1" />
            </geometry>
        </collision>
        <inertial>
            <origin rpy="0 0.6 1.57" xyz="-0.4 -3.0 3.2" />
            <mass value="160" />
            <!-- <inertial>
      <mass value="${mass}" /> -->
            <inertia ixx="37.499985" ixy="0.0" ixz="0.0" iyy="525.7497897" iyz="0.0" izz="525.7497897" />
            <!-- </inertial> -->
        </inertial>
    </link>
    <!-- Brazo B -->
    <link name="brazo_b">
        <visual>
            <origin rpy="0 0.6 1.57" xyz="0 0 -0.2" />
            <geometry>
                <mesh filename="package://rockbreaker_arm_simulator/rockbreaker_description/meshes/BrazoB_rockbreaker.dae" scale="1 1 1" />
            </geometry>
        </visual>
        <collision>
            <origin rpy="0 0.6 1.57" xyz="0 0 -0.2" />
            <geometry>
                <mesh filename="package://rockbreaker_arm_simulator/rockbreaker_description/meshes/BrazoB_rockbreaker.dae" scale="1 1 1" />
            </geometry>
        </collision>
        <inertial>
            <origin rpy="0 0.6 1.57" xyz="0.5 -4.0 2.8" />
            <mass value="80" />
            <!-- <inertial>
      <mass value="${mass}" /> -->
            <inertia ixx="21.666657999999998" ixy="0.0" ixz="0.0" iyy="254.999898" iyz="0.0" izz="246.66656799999998" />
            <!-- </inertial> -->
        </inertial>
    </link>
    <!-- Hydraulic Hammer -->
    <link name="h_hammer">
        <visual>
            <origin rpy="0 1.57 1.57" xyz="0 0 -0.2" />
            <geometry>
                <mesh filename="package://rockbreaker_arm_simulator/rockbreaker_description/meshes/Hydraulic_Hammer.dae" scale="1 1 1" />
            </geometry>
        </visual>
        <collision>
            <origin rpy="0 1.57 1.57" xyz="0 0 -0.2" />
            <geometry>
                <mesh filename="package://rockbreaker_arm_simulator/rockbreaker_description/meshes/Hydraulic_Hammer.dae" scale="1 1 1" />
            </geometry>
        </collision>
        <inertial>
            <origin rpy="0 1.57 1.57" xyz="-0.4 -1.5 0.2" />
            <mass value="40" />
            <!-- <inertial>
      <mass value="${mass}" /> -->
            <inertia ixx="18.96665908" ixy="0.0" ixz="0.0" iyy="16.66666" iyz="0.0" izz="8.966663080000002" />
            <!-- </inertial> -->
        </inertial>
    </link>
    <!-- Joints of Rockbreaker Arm -->
    <joint name="joint_base_rockbreaker" type="revolute">
        <axis xyz="0 0 1" />
        <limit effort="1000000" lower="-1.57" upper="1.57" velocity="1" />
        <parent link="rockbreaker_base" />
        <child link="rockbreaker_baserotatoria" />
        <origin rpy="0 0 0" xyz="0 0 1.1 " />
        <dynamics damping="1.0" friction="0.1" />
    </joint>
    <joint name="joint_brazoa" type="revolute">
        <axis xyz="1 0 0" />
        <limit effort="1000000" lower="-0.4886" upper="0.4014" velocity="1" />
        <parent link="rockbreaker_baserotatoria" />
        <child link="brazo_a" />
        <origin rpy="0 0 0" xyz="0.375 0.05 1.2" />
        <dynamics damping="1.0" friction="0.1" />
    </joint>
    <joint name="joint_brazob" type="revolute">
        <axis xyz="1 0 0" />
        <limit effort="100000" lower="0.7699" upper="2.7053" velocity="1" />
        <parent link="brazo_a" />
        <child link="brazo_b" />
        <origin rpy="0 0 0" xyz="-0.9 -6.75 4.6" />
        <dynamics damping="1.0" friction="0.1" />
    </joint>
    <joint name="joint_hammer" type="revolute">
        <axis xyz="1 0 0" />
        <limit effort="100000" lower="-0.9250" upper="1.6930" velocity="1" />
        <parent link="brazo_b" />
        <child link="h_hammer" />
        <origin rpy="0 0 0" xyz="0.875 -6.82 4.68" />
        <dynamics damping="1.0" friction="0.1" />
    </joint>
    <!-- Transmission of Joints -->
    <transmission name="tran1">
        <type>transmission_interface/SimpleTransmission</type>
        <joint name="joint_base_rockbreaker">
            <hardwareInterface>hardware_interface/PositionJointInterface</hardwareInterface>
        </joint>
        <actuator name="motor1">
            <hardwareInterface>hardware_interface/PositionJointInterface</hardwareInterface>
            <mechanicalReduction>1</mechanicalReduction>
        </actuator>
    </transmission>
    <transmission name="tran2">
        <type>transmission_interface/SimpleTransmission</type>
        <joint name="joint_brazoa">
            <hardwareInterface>hardware_interface/PositionJointInterface</hardwareInterface>
        </joint>
        <actuator name="motor2">
            <hardwareInterface>hardware_interface/PositionJointInterface</hardwareInterface>
            <mechanicalReduction>1</mechanicalReduction>
        </actuator>
    </transmission>
    <transmission name="tran3">
        <type>transmission_interface/SimpleTransmission</type>
        <joint name="joint_brazob">
            <hardwareInterface>hardware_interface/PositionJointInterface</hardwareInterface>
        </joint>
        <actuator name="motor3">
            <hardwareInterface>hardware_interface/PositionJointInterfacee</hardwareInterface>
            <mechanicalReduction>1</mechanicalReduction>
        </actuator>
    </transmission>
    <transmission name="tran4">
        <type>transmission_interface/SimpleTransmission</type>
        <joint name="joint_hammer">
            <hardwareInterface>hardware_interface/PositionJointInterface</hardwareInterface>
        </joint>
        <actuator name="motor4">
            <hardwareInterface>hardware_interface/PositionJointInterface</hardwareInterface>
            <mechanicalReduction>1</mechanicalReduction>
        </actuator>
    </transmission>
    <!-- Lidar OS1-64 #1-->
    <!-- <xacro:include filename="$(find lidar_description)/urdf/OS0-128.urdf.xacro"/>
  <xacro:OS0-128 parent="rockbreaker_base" name="OS0-128" topic="/os0_cloud_node/points" samples="256" >
    <origin xyz="10.85 -12.9 -0.1" rpy="0 0 2.57" />
  </xacro:OS0-128> -->
</robot>

